#VRML_SIM R2022b utf8

EXTERNPROTO "https://raw.githubusercontent.com/cyberbotics/webots/R2022b/projects/objects/backgrounds/protos/TexturedBackground.proto"
EXTERNPROTO "https://raw.githubusercontent.com/cyberbotics/webots/R2022b/projects/objects/lights/protos/CeilingLight.proto"

WorldInfo {
  info [
    "iRobot Create simulation"
    "The vacuum cleaner robot goes randomly into the apartment while a supervisor tracks its position and alterates the ground texture."
    "The robot can be stopped by the virtual walls emitting IR light."
  ]
  title "iRobot Create"
}
Viewpoint {
  orientation -0.38400067833958146 0.41572749823090144 0.8244477704799846 1.8208553318683918
  position 1.7871345004647028 -14.540612602649537 18.776258229176587
  near 0.1
}
TexturedBackground {
}
CeilingLight {
  translation 1.82639 -1.29685 2.4
  pointLightColor 1 1 0.9372549019607843
  pointLightIntensity 7
}
CeilingLight {
  translation -3.25511 1.9443400000000004 2.4
  name "ceiling light(2)"
  pointLightIntensity 6
}
DEF diff_robot Robot {
  translation -4.9 0.0774321 0.039721
  rotation 1.1307671648220746e-09 2.079022491720665e-09 0.9999999999999999 0
  children [
    GPS {
    }
    InertialUnit {
      name "imu"
    }
    DEF BODY Shape {
      appearance PBRAppearance {
        baseColor 0.917647 0.145098 0.145098
        roughness 1
        metalness 0
      }
      geometry Box {
        size 0.2 0.1 0.05
      }
    }
    DEF WHEEL1 HingeJoint {
      jointParameters HingeJointParameters {
        position 5560.933513033018
        axis 0 1 0
        anchor 0.05 0.06 0
      }
      device [
        RotationalMotor {
          name "wheel1"
        }
      ]
      endPoint Solid {
        translation 0.05 0.06 0
        rotation -0.9757667074427786 -0.15472420104119858 0.1547247693759534 4.687856018076553
        children [
          DEF WHEEL Shape {
            appearance PBRAppearance {
              baseColor 0.305882 0.898039 0.25098
              roughness 1
              metalness 0
            }
            geometry Cylinder {
              height 0.02
              radius 0.04
              subdivision 24
            }
          }
        ]
        boundingObject USE WHEEL
        physics Physics {
        }
      }
    }
    DEF WHEEL2 HingeJoint {
      jointParameters HingeJointParameters {
        position 6028.491744396439
        axis 0 1 0
        anchor 0.05 -0.06 0
      }
      device [
        RotationalMotor {
          name "wheel2"
        }
      ]
      endPoint Solid {
        translation 0.05 -0.06 0
        rotation -0.0794764467292172 -0.7048687269323555 0.704871316062768 3.3002115539241252
        children [
          USE WHEEL
        ]
        name "solid(1)"
        boundingObject USE WHEEL
        physics Physics {
        }
      }
    }
    DEF WHEEL3 HingeJoint {
      jointParameters HingeJointParameters {
        position 5561.155757042348
        axis 0 1 0
        anchor -0.05 0.06 0
      }
      device [
        RotationalMotor {
          name "wheel3"
        }
      ]
      endPoint Solid {
        translation -0.05 0.06 0
        rotation -0.9319920006062014 -0.25631077638318917 0.25631171786693024 4.64201242603907
        children [
          USE WHEEL
        ]
        name "solid(2)"
        boundingObject USE WHEEL
        physics Physics {
        }
      }
    }
    DEF WHEEL4 HingeJoint {
      jointParameters HingeJointParameters {
        position 6028.684955510667
        axis 0 1 0
        anchor -0.05 -0.06 0
      }
      device [
        RotationalMotor {
          name "wheel4"
        }
      ]
      endPoint Solid {
        translation -0.05 -0.06 0
        rotation -0.011082989235204614 -0.7070620533585197 0.7070646505448042 3.1637576431439163
        children [
          USE WHEEL
        ]
        name "solid(3)"
        boundingObject USE WHEEL
        physics Physics {
        }
      }
    }
    DEF DS_RIGHT DistanceSensor {
      translation 0.1 -0.03 0
      rotation 0 0 1 -0.3
      children [
        Shape {
          appearance PBRAppearance {
            baseColor 0.184314 0.596078 0.847059
            roughness 1
            metalness 0
          }
          geometry Box {
            size 0.01 0.01 0.01
          }
        }
      ]
      name "ds_right"
    }
    DEF DS_LEFT DistanceSensor {
      translation 0.1 0.03 0
      rotation 0 0 1 0.3
      children [
        Shape {
          appearance PBRAppearance {
            baseColor 0.184314 0.596078 0.847059
            roughness 1
            metalness 0
          }
          geometry Box {
            size 0.01 0.01 0.01
          }
        }
      ]
      name "ds_left"
    }
  ]
  name "robot(1)"
  boundingObject USE BODY
  physics Physics {
    density -1
    mass 1
  }
  controller "point_follower"
}
Robot {
  children [
    Solid {
      children [
        Shape {
          appearance PBRAppearance {
            baseColorMap ImageTexture {
              url [
                "textures/logo.png"
              ]
            }
            metalness 0
          }
          geometry Plane {
            size 10 10
          }
        }
      ]
    }
    Display {
      translation 0 0 0.01
      children [
        Shape {
          appearance PBRAppearance {
            baseColor 1 0.6 1
            baseColorMap ImageTexture {
              url [
                "textures/sin.png"
              ]
            }
            roughness 0.5
            metalness 0
          }
          geometry Plane {
            size 9.9 9.9
          }
        }
      ]
      name "ground_display"
      width 500
      height 500
    }
  ]
  boundingObject Plane {
    size 9.9 9.9
  }
  locked TRUE
  controller "ground"
  supervisor TRUE
}
