#VRML_SIM R2022b utf8

EXTERNPROTO "https://raw.githubusercontent.com/cyberbotics/webots/R2022b/projects/objects/backgrounds/protos/TexturedBackground.proto"
EXTERNPROTO "https://raw.githubusercontent.com/cyberbotics/webots/R2022b/projects/objects/lights/protos/CeilingLight.proto"

WorldInfo {
  info [
    "iRobot Create simulation"
    "The vacuum cleaner robot goes randomly into the apartment while a supervisor tracks its position and alterates the ground texture."
    "The robot can be stopped by the virtual walls emitting IR light."
  ]
  title "iRobot Create"
}
Viewpoint {
  orientation -0.38400067833958146 0.41572749823090144 0.8244477704799846 1.8208553318683918
  position -3.091765152045214 -17.007706386828303 22.767939504019292
  near 0.1
}
TexturedBackground {
}
CeilingLight {
  translation 1.82639 -1.29685 2.4
  pointLightColor 1 1 0.9372549019607843
  pointLightIntensity 7
}
CeilingLight {
  translation -3.25511 1.9443400000000004 2.4
  name "ceiling light(2)"
  pointLightIntensity 6
}
DEF diff_robot Robot {
  translation -2.877296712931533 -6.092803385906172 0.039720979298627716
  rotation 6.023188975564785e-09 -4.367356253497319e-09 -1 1.254006976831002
  children [
    GPS {
    }
    InertialUnit {
      name "imu"
    }
    DEF BODY Shape {
      appearance PBRAppearance {
        baseColor 0.917647 0.145098 0.145098
        roughness 1
        metalness 0
      }
      geometry Box {
        size 0.2 0.1 0.05
      }
    }
    DEF WHEEL1 HingeJoint {
      jointParameters HingeJointParameters {
        position 5726.261507301791
        axis 0 1 0
        anchor 0.05 0.06 0
      }
      device [
        RotationalMotor {
          name "wheel1"
        }
      ]
      endPoint Solid {
        translation 0.05 0.06 0
        rotation -0.3091790642483026 -0.6724600300960284 0.6724625001840567 3.741303651646231
        children [
          DEF WHEEL Shape {
            appearance PBRAppearance {
              baseColor 0.305882 0.898039 0.25098
              roughness 1
              metalness 0
            }
            geometry Cylinder {
              height 0.02
              radius 0.04
              subdivision 24
            }
          }
        ]
        boundingObject USE WHEEL
        physics Physics {
        }
        linearVelocity 0.012460691377599451 -0.038009619821137125 -4.2705427862867793e-10
        angularVelocity 0.9502404847496654 0.3115172887421733 3.946432535782949e-09
      }
    }
    DEF WHEEL2 HingeJoint {
      jointParameters HingeJointParameters {
        position 6187.835749032482
        axis 0 1 0
        anchor 0.05 -0.06 0
      }
      device [
        RotationalMotor {
          name "wheel2"
        }
      ]
      endPoint Solid {
        translation 0.05 -0.06 0
        rotation -0.7548946909841155 0.46375231835129715 -0.4637540218130663 4.434841837362323
        children [
          USE WHEEL
        ]
        name "solid(1)"
        boundingObject USE WHEEL
        physics Physics {
        }
        linearVelocity 0.012460691157398965 -0.0380096191412634 4.2726207486836943e-10
        angularVelocity 0.9502404846748864 0.31151728878732055 4.1576715092254505e-09
      }
    }
    DEF WHEEL3 HingeJoint {
      jointParameters HingeJointParameters {
        position 5726.483752375132
        axis 0 1 0
        anchor -0.05 0.06 0
      }
      device [
        RotationalMotor {
          name "wheel3"
        }
      ]
      endPoint Solid {
        translation -0.05 0.06 0
        rotation -0.22802316509734133 -0.6884772886452997 0.6884798175681021 3.5899711906295124
        children [
          USE WHEEL
        ]
        name "solid(2)"
        boundingObject USE WHEEL
        physics Physics {
        }
        linearVelocity 0.012460691943582774 -0.038009619635575476 -4.277616339717983e-10
        angularVelocity 0.9502404847572821 0.3115172887189539 3.950444618091721e-09
      }
    }
    DEF WHEEL4 HingeJoint {
      jointParameters HingeJointParameters {
        position 6188.02896124877
        axis 0 1 0
        anchor -0.05 -0.06 0
      }
      device [
        RotationalMotor {
          name "wheel4"
        }
      ]
      endPoint Solid {
        translation -0.05 -0.06 0
        rotation -0.8228384824793855 0.4018305896374463 -0.401832065647634 4.518614129577164
        children [
          USE WHEEL
        ]
        name "solid(3)"
        boundingObject USE WHEEL
        physics Physics {
        }
        linearVelocity 0.012460691723390167 -0.038009618955695434 4.265534472594196e-10
        angularVelocity 0.9502404846694308 0.3115172888039699 4.143131309559387e-09
      }
    }
    DEF DS_RIGHT DistanceSensor {
      translation 0.1 -0.03 0
      rotation 0 0 1 -0.3
      children [
        Shape {
          appearance PBRAppearance {
            baseColor 0.184314 0.596078 0.847059
            roughness 1
            metalness 0
          }
          geometry Box {
            size 0.01 0.01 0.01
          }
        }
      ]
      name "ds_right"
    }
    DEF DS_LEFT DistanceSensor {
      translation 0.1 0.03 0
      rotation 0 0 1 0.3
      children [
        Shape {
          appearance PBRAppearance {
            baseColor 0.184314 0.596078 0.847059
            roughness 1
            metalness 0
          }
          geometry Box {
            size 0.01 0.01 0.01
          }
        }
      ]
      name "ds_left"
    }
  ]
  name "robot(1)"
  boundingObject USE BODY
  physics Physics {
    density -1
    mass 1
  }
  controller "point_follower"
  linearVelocity 0.012460691550492455 -0.03800961938841799 -2.502247298126992e-13
  angularVelocity -2.2689933262498867e-09 6.898082188827066e-09 -4.812516307712231e-09
}
Robot {
  children [
    Solid {
      children [
        Shape {
          appearance PBRAppearance {
            baseColorMap ImageTexture {
              url [
                "textures/logo.png"
              ]
            }
            metalness 0
          }
          geometry Plane {
            size 10 10
          }
        }
      ]
    }
    Display {
      translation 0 0 0.01
      children [
        Shape {
          appearance PBRAppearance {
            baseColor 1 0.6 1
            baseColorMap ImageTexture {
              url [
                "textures/sin.png"
              ]
            }
            roughness 0.5
            metalness 0
          }
          geometry Plane {
            size 9.9 9.9
          }
        }
      ]
      name "ground_display"
      width 500
      height 500
    }
  ]
  boundingObject Plane {
    size 9.9 9.9
  }
  locked TRUE
  controller "ground"
  supervisor TRUE
}
