#VRML_SIM R2022b utf8

EXTERNPROTO "https://raw.githubusercontent.com/cyberbotics/webots/R2022b/projects/objects/backgrounds/protos/TexturedBackground.proto"
EXTERNPROTO "https://raw.githubusercontent.com/cyberbotics/webots/R2022b/projects/objects/lights/protos/CeilingLight.proto"

WorldInfo {
  info [
    "iRobot Create simulation"
    "The vacuum cleaner robot goes randomly into the apartment while a supervisor tracks its position and alterates the ground texture."
    "The robot can be stopped by the virtual walls emitting IR light."
  ]
  title "iRobot Create"
}
Viewpoint {
  orientation -0.31399587855865496 0.3332343959156959 0.8890227362823065 1.7162197078827113
  position 0.9102542814289836 -13.019691138830277 10.193146837653144
  near 0.1
}
TexturedBackground {
}
CeilingLight {
  translation 1.82639 -1.29685 2.4
  pointLightColor 1 1 0.9372549019607843
  pointLightIntensity 7
}
CeilingLight {
  translation -3.25511 1.9443400000000004 2.4
  name "ceiling light(2)"
  pointLightIntensity 6
}
DEF diff_robot Robot {
  translation 0 0 0.039721
  rotation 5.788330347526398e-06 -4.4091638469117035e-05 0.9999999990112113 0
  children [
    GPS {
    }
    InertialUnit {
      name "imu"
    }
    DEF BODY Shape {
      appearance PBRAppearance {
        baseColor 0.917647 0.145098 0.145098
        roughness 1
        metalness 0
      }
      geometry Box {
        size 0.2 0.1 0.05
      }
    }
    DEF WHEEL1 HingeJoint {
      jointParameters HingeJointParameters {
        position 5558.693513038207
        axis 0 1 0
        anchor 0.05 0.06 0
      }
      device [
        RotationalMotor {
          name "wheel1"
        }
      ]
      endPoint Solid {
        translation 0.05 0.06 0
        rotation -0.44158182884916963 0.6344298745646029 -0.6344322049598088 3.9732526593784034
        children [
          DEF WHEEL Shape {
            appearance PBRAppearance {
              baseColor 0.305882 0.898039 0.25098
              roughness 1
              metalness 0
            }
            geometry Cylinder {
              height 0.02
              radius 0.04
              subdivision 24
            }
          }
        ]
        boundingObject USE WHEEL
        physics Physics {
        }
      }
    }
    DEF WHEEL2 HingeJoint {
      jointParameters HingeJointParameters {
        position 6026.251744404982
        axis 0 1 0
        anchor 0.05 -0.06 0
      }
      device [
        RotationalMotor {
          name "wheel2"
        }
      ]
      endPoint Solid {
        translation 0.05 -0.06 0
        rotation -0.8951776073943921 -0.315163704694613 0.31516486235432145 4.601877800397627
        children [
          USE WHEEL
        ]
        name "solid(1)"
        boundingObject USE WHEEL
        physics Physics {
        }
      }
    }
    DEF WHEEL3 HingeJoint {
      jointParameters HingeJointParameters {
        position 5558.9157570495845
        axis 0 1 0
        anchor -0.05 0.06 0
      }
      device [
        RotationalMotor {
          name "wheel3"
        }
      ]
      endPoint Solid {
        translation -0.05 0.06 0
        rotation -0.5264189011574351 0.6011990041601477 -0.6012012124913301 4.110706966112106
        children [
          USE WHEEL
        ]
        name "solid(2)"
        boundingObject USE WHEEL
        physics Physics {
        }
      }
    }
    DEF WHEEL4 HingeJoint {
      jointParameters HingeJointParameters {
        position 6026.444955519259
        axis 0 1 0
        anchor -0.05 -0.06 0
      }
      device [
        RotationalMotor {
          name "wheel4"
        }
      ]
      endPoint Solid {
        translation -0.05 -0.06 0
        rotation -0.8356158958979291 -0.3884230722746805 0.388424499030892 4.53375674080102
        children [
          USE WHEEL
        ]
        name "solid(3)"
        boundingObject USE WHEEL
        physics Physics {
        }
      }
    }
    DEF DS_RIGHT DistanceSensor {
      translation 0.1 -0.03 0
      rotation 0 0 1 -0.3
      children [
        Shape {
          appearance PBRAppearance {
            baseColor 0.184314 0.596078 0.847059
            roughness 1
            metalness 0
          }
          geometry Box {
            size 0.01 0.01 0.01
          }
        }
      ]
      name "ds_right"
    }
    DEF DS_LEFT DistanceSensor {
      translation 0.1 0.03 0
      rotation 0 0 1 0.3
      children [
        Shape {
          appearance PBRAppearance {
            baseColor 0.184314 0.596078 0.847059
            roughness 1
            metalness 0
          }
          geometry Box {
            size 0.01 0.01 0.01
          }
        }
      ]
      name "ds_left"
    }
  ]
  name "robot(1)"
  boundingObject USE BODY
  physics Physics {
    density -1
    mass 1
  }
  controller "point_follower"
}
Robot {
  children [
    Solid {
      children [
        Shape {
          appearance PBRAppearance {
            baseColorMap ImageTexture {
              url [
                "textures/logo.png"
              ]
            }
            metalness 0
          }
          geometry Plane {
            size 10 10
          }
        }
      ]
    }
    Display {
      translation 0 0 0.01
      rotation 0 0 1 1.57
      children [
        Shape {
          appearance PBRAppearance {
            baseColor 1 0.6 1
            baseColorMap ImageTexture {
              url [
                "textures/black.png"
              ]
            }
            roughness 0.5
            metalness 0
          }
          geometry Plane {
            size 9.9 9.9
          }
        }
      ]
      name "ground_display"
      width 500
      height 500
    }
  ]
  boundingObject Plane {
    size 9.9 9.9
  }
  locked TRUE
  controller "ground"
  supervisor TRUE
}
